Workbook

Sheet 요약
A1: BeOne 임상 교차 비교 요약 — Q2 2026 Appendix vs. 의약품안전나라(nedrug)
A2: 작성일 2026-10-13 · 아래 집계 값은 모두 다른 시트를 참조하는 수식임
A4: 1. 비교 대상
A5: 자료 | B5: 기준일 | C5: 범위
A6: A. Q2 2026 Clinical Trials Appendix | B6: 2026-07-24 | C6: 글로벌 프로토콜 단위 (발표 2026-08-05), p.12–23
A7: B. nedrug 임상시험정보검색 | B7: 2026-10-13 | C7: 의뢰자 = 비원메디슨코리아 유한회사, 국내 승인 2023-11-23 ~ 2026-10-02
A8: C. nedrug 의약품등제품정보목록 | B8: 2026-10-13 | C8: 업체 = 비원메디슨코리아(유)
A9: D. Global clinical development pipeline | B9: 2026-08-03 | C9: 판정 시 '8월 파이프라인 표기' 참고용
A11: 2. 집계 (수식)
A12: nedrug 국내 시험 수 | B12: =COUNTA(시험별비교!$A$5:$A$25) -> 21 | C12: B 파일 전체
A13: └ 진행 중 | B13: =COUNTIF(시험별비교!$C$5:$C$25,"진행중") -> 15 | C13: 모집중 + 승인완료(모집 전) + 모집완료
A14: └ 종료 | B14: =COUNTIF(시험별비교!$C$5:$C$25,"종료") -> 6
A15: Appendix 프로토콜과 1:1 매칭 | B15: =COUNTIF(시험별비교!$N$5:$N$25,"매칭") -> 16
A16: Appendix 미수록 | B16: =COUNTIF(시험별비교!$N$5:$N$25,"미수록") -> 5 | C16: 신규 2상 1건 + 파이프라인에서 제외된 종료 과제
A17: 확인 필요 | B17: =COUNTIF(시험별비교!$O$5:$O$25,"확인 필요") -> 2 | C17: BG-C477 신규 2상 / BG-C137 국내만 종료
A18: 진행 중 3상 | B18: =COUNTIFS(시험별비교!$C$5:$C$25,"진행중",시험별비교!$H$5:$H$25,"3상") -> 8
A19: 진행 중 2상 | B19: =COUNTIFS(시험별비교!$C$5:$C$25,"진행중",시험별비교!$H$5:$H$25,"2상") -> 1
A20: 진행 중 1상 | B20: =COUNTIFS(시험별비교!$C$5:$C$25,"진행중",시험별비교!$H$5:$H$25,"1상") -> 6
A21: 진행 중 혈액암 | B21: =COUNTIFS(시험별비교!$C$5:$C$25,"진행중",시험별비교!$G$5:$G$25,"혈액암") -> 6
A22: 진행 중 고형암 | B22: =COUNTIFS(시험별비교!$C$5:$C$25,"진행중",시험별비교!$G$5:$G$25,"고형암") -> 9
A23: 2026년 국내 신규 승인 | B23: =COUNTIFS(시험별비교!$D$5:$D$25,">="&DATE(2026,1,1)) -> 5 | C23: 국내 승인일 기준
A24: 국내 실시기관 수 (진행 중 시험, 중복 제거) | B24: =COUNTIF(실시기관!$W$8:$W$37,">0") -> 30 | C24: 실시기관 시트
A25: 국내 실시기관 수 (전체 21건) | B25: =COUNTA(실시기관!$A$8:$A$37) -> 30
A26: Appendix 전체 시험 수 | B26: =COUNTA(Appendix전체대조!$E$5:$E$90) -> 86 | C26: p.12–22
A27: └ 이 중 국내 nedrug 등재 | B27: =COUNT(Appendix전체대조!$P$5:$P$90) -> 16
A28: └ 진행·유지 중인 시험 | B28: =COUNTIF(Appendix전체대조!$O$5:$O$90,"진행")+COUNTIF(Appendix전체대조!$O$5:$O$90,"유지") -> 54 | C28: 승인·종료 제외
A29: BeOne 국내 판권 보유 제품 | B29: =COUNTIF(제품비교!$F$5:$F$21,"Y") -> 4 | C29: Global 3 + APAC 1
A30: └ 국내 허가 | B30: =COUNTIF(제품비교!$G$5:$G$21,"허가") -> 3 | C30: 브루킨사, 테빔브라, 지헤라
A31: └ 국내 미허가 | B31: =COUNTIF(제품비교!$G$5:$G$21,"미허가") -> 1 | C31: BEQALZI (sonrotoclax)
A33: 3. 핵심 발견
A34: 매칭률 | B34: nedrug 21건 중 16건이 Appendix 프로토콜과 1:1로 맞음. 미수록 5건은 신규 2상 1건(BG-C477)과 파이프라인에서 제외된 종료 과제 4건(BGB-53038, BGB-A3055, BG-60366, BGB-A445/LC-203).
A35: 확인 필요 ① BG-C477 2상 | B35: 2026-10-02 국내 승인. Appendix와 8월 파이프라인에는 BG-C477이 Ph1(101)로만 나옴 → 공시 이후 새로 시작한 2상(CEA 고발현 비편평 NSCLC)으로 보임.
A36: 확인 필요 ② BG-C137 1상 | B36: nedrug에는 '종료'로 나오지만 Appendix는 Dose Escalation(진행 중)이고 8월 파이프라인에도 있음 → 한국 사이트만 종료했을 가능성.
A37: BEQALZI 국내 미허가 | B37: 글로벌 판권 제품 중 유일한 국내 미허가 품목. 그런데 CELESTIAL 3상 4건(301·302·303·304)에 한국이 모두 참여 중 → 다음 국내 허가 후보.
A38: KANDELA-302 최대 규모 | B38: BGB-43395-302는 국내 실시기관 25곳으로 BeOne 국내 임상 중 가장 큼. 국내 승인(2026-04-09)이 글로벌 'New to pivotal' 공시(2026-08-05)보다 앞섬.
A39: 핵심 실시기관 | B39: 서울대병원·세브란스병원(각 14건), 분당서울대·삼성서울(각 13건), 서울아산(12건)이 진행 중 15건 대부분에 참여.
A41: 4. 해석 시 주의
A42: • nedrug B 파일에는 2023-11-23 이후 국내 승인 건만 있음. BRUKINSA·TEVIMBRA 허가 근거가 된 이전 시험(ALPINE, RATIONALE 등)은 빠져 있음.
A43: • 의뢰자 '비원메디슨코리아' 기준 검색이라, 파트너사가 주도하는 시험(Amgen tarlatamab DeLLphi, Jazz zanidatamab HERIZON)은 목록에 없음. 목록에 없다고 한국 미참여로 단정하면 안 됨.
A44: • MOA·치료영역·대상 요약·판정·비고는 원문을 대조해 작성자가 정리한 값임.
...

Sheet 시험별비교
A1: 시험별 1:1 비교 — nedrug 임상시험정보 ↔ Q2 2026 Clinical Trial Appendix
A2: nedrug 21건(의뢰자: 비원메디슨코리아 유한회사, 2026-10-13 검색)을 Appendix(As of 2026-07-24) 프로토콜과 대조
A4: No | B4: 국내 상태 (nedrug) | C4: 진행 구분 | D4: 국내 승인일 | E4: 제품 (nedrug) | F4: MOA | G4: 치료영역 | H4: 단계 | I4: 대상 / 디자인 요약 | J4: Appendix 프로토콜 | K4: NCT | L4: Appendix 상태 | M4: 8월 파이프라인 표기 | N4: Appendix 매칭 | O4: 판정 | P4: 비고 | Q4: 국내 실시기관 수 | R4: 국내 실시기관 (중복 제거) | S4: 임상시험 제목 (nedrug 원문)
A5: 1 | B5: 승인완료 | C5: =IF(B5="종료","종료","진행중") -> 진행중 | D5: 46297 | E5: BG-C477 | F5: CEA ADC | G5: 고형암 | H5: 2상 | I5: 기치료 CEA 고발현 비편평 NSCLC (EGFR 변이 없음), 단일군 공개 | M5: Ph1 101만 표기 | N5: 미수록 | O5: 확인 필요 | P5: 8월 공시 이후 국내 승인된 신규 2상으로 추정. Q3 공시에 'New to Phase II'로 반영되는지 확인 필요 | Q5: =실시기관!B38 -> 6 | R5: 서울대병원, 국립암센터, 서울아산병원, 분당서울대병원, 세브란스병원, 삼성서울병원 | S5: 이전에 치료받았으며 사람 표피 성장 인자 수용체(EGFR) 유전체 변이가 없는 암 배아 항원(CEA) 고발현 비편평 비소세포폐암(NSCLC) 환자를 대상으로 BG-C477 의 유효성 및 안전성을 조사하기 위한 단일군, 공개 제 2 상 임상시험
A6: 2 | B6: 승인완료 | C6: =IF(B6="종료","종료","진행중") -> 진행중 | D6: 46239 | E6: BG-75098, BGB-43395 | F6: CDK2 CDAC | G6: 고형암 | H6: 1상 | I6: 진행성 고형암, 단독·병용 1a/1b | J6: BG-75098-101 | K6: NCT07226349 | L6: Dose Escalation | M6: Ph1 101 Solid tumors | N6: 매칭 | O6: 일치 | P6: 국내는 승인 후 모집 전 | Q6: =실시기관!C38 -> 5 | R6: 세브란스병원, 서울아산병원, 삼성서울병원, 국립암센터, 서울대병원 | S6: 진행성 고형 종양 환자를 대상으로 BG-75098 단독요법 및 다른 제제와의 병용요법의 안전성, 내약성, 약동학, 약력학 및 예비 항종양 활성을 평가하는 제1a/1b상 공개 임상시험
A7: 3 | B7: 모집중 | C7: =IF(B7="종료","종료","진행중") -> 진행중 | D7: 46183 | E7: BG-C477 | F7: CEA ADC | G7: 고형암 | H7: 1상 | I7: 진행성 고형암, 인간 대상 최초(FIH) 1a/b | J7: BG-C477-101 | K7: NCT06596473 | L7: Dose Escalation | M7: Ph1 101 Solid tumors | N7: 매칭 | O7: 일치 | P7: 글로벌 개시 이후 한국이 늦게 참여 | Q7: =실시기관!D38 -> 4 | R7: 서울아산병원, 분당서울대병원, 세브란스병원, 삼성서울병원 | S7: 선정된 진행성 고형 종양이 있는 환자를 대상으로 BG-C477의 안전성, 내약성, 약물동태, 약물동력 및 예비 항종양 활성을 조사하는 다기관, 공개, 제1a/b상, 인간 대상 최초 임상시험
A8: 4 | B8: 모집중 | C8: =IF(B8="종료","종료","진행중") -> 진행중 | D8: 46121 | E8: BGB-43395 | F8: CDK4i | G8: 고형암 | H8: 3상 | I8: 1L HR+/HER2- 진행성·전이성 유방암, +letrozole vs CDK4/6i(abema·palbo·ribo)+letrozole | J8: BGB-43395-302 (KANDELA-302) | K8: NCT07492641 | L8: Enrolling | M8: Ph3 302 1L HR+/HER2- BC | N8: 매칭 | O8: 일치 | P8: Q2 'New to pivotal' 과제. 국내 25개 기관으로 BeOne 국내 임상 중 최대 규모 | Q8: =실시기관!E38 -> 25 | R8: 중앙대병원, 충북대병원, 해운대백병원, 화순전남대병원, 고대안산병원, 계명대동산병원, 이대목동병원, 동아대병원, 분당차병원, 순천향대천안병원, 강남세브란스병원, 인하대병원, 울산대병원, 아주대병원, 성빈센트병원, 고대구로병원, 국립암센터, 서울대병원, 서울성모병원, 고대안암병원, 분당서울대병원, 길병원, 삼성서울병원, 서울아산병원, 세브란스병원 | S8: 진행성 또는 전이성 질병에 대해 이전 전신 항암요법을 받지 않은 진행성 또는 전이성 HR+/HER2- 유방암 환자를 대상으로 BGB-43395 및 레트로졸 병용요법 대 CDK4/6 억제제(아베마시클립, 팔보시클립, 리보시클립) 및 레트로졸 병용요법의 유효성 및 안전성을 조사하는 공개, 무작위배정, 다기관 제3상 임상시험
A9: 5 | B9: 모집중 | C9: =IF(B9="종료","종료","진행중") -> 진행중 | D9: 46029 | E9: BGB-11417(손로토클락스) | F9: BCL2i | G9: 혈액암 | H9: 3상 | I9: TN CLL, sonro+zanu vs ven+acalabrutinib | J9: BGB-11417-304 (CELESTIAL-TNCLL2) | K9: NCT07277231 | L9: Enrolling | M9: Ph3 304 TN CLL (vs. AV) | N9: 매칭 | O9: 일치 | Q9: =실시기관!F38 -> 5 | R9: 분당서울대병원, 서울성모병원, 서울아산병원, 세브란스병원, 서울대병원 | S9: 이전에 치료받지 않은 만성 림프구성 백혈병 환자에서 손로토클락스(BGB-11417) 및 자누브루티닙(BGB-3111)의 병용을 베네토클락스 및 아칼라브루티닙의 병용과 비교하는 제3상, 공개, 무작위배정 시험
A10: 6 | B10: 모집중 | C10: =IF(B10="종료","종료","진행중") -> 진행중 | D10: 45954 | E10: BG-T187 | F10: EGFR×MET×MET tsAb | G10: 고형암 | H10: 1상 | I10: 진행성 고형암, 단독·병용 | J10: BG-T187-101 | K10: NCT06598800 | L10: Dose Escalation | M10: Ph1 101 Solid tumors | N10: 매칭 | O10: 일치 | P10: nedrug 표기는 'EGFR×MET 삼중 특이성 항체' | Q10: =실시기관!G38 -> 7 | R10: 삼성서울병원, 서울대병원, 서울아산병원, 세브란스병원, 분당서울대병원, 서울성모병원, 성빈센트병원 | S10: 진행성 고형 종양에서 EGFR×MET 삼중 특이성 항체인 BG-T187 단독 요법 및 다른 치료제와 병용 요법의 안전성, 내약성, 약동학 및 예비 항종양 활성을 조사하기 위한 제1상 임상시험
A11: 7 | B11: 모집중 | C11: =IF(B11="종료","종료","진행중") -> 진행중 | D11: 45908 | E11: 티슬렐리주맙(BGB-A317) | F11: PD-1 mAb | G11: 고형암 | H11: 3상 | I11: 1L 절제불가 국소진행·전이성 위/위식도접합부 선암, SC vs IV + 화학요법 | J11: BGB-A317-316 | K11: NCT07043400 | L11: Enrolling | M11: Ph3 316 SubQ | N11: 매칭 | O11: 일치 | P11: Appendix에는 'SubQ Formulation'으로만 표기됨. 적응증(위암)은 nedrug에서 확인 | Q11: =실시기관!H38 -> 6 | R11: 칠곡경북대병원, 삼성서울병원, 서울아산병원, 분당서울대병원, 서울대병원, 세브란스병원 | S11: 절제 불가능한 국소 진행성 또는 전이성, 위 또는 위식도 접합부 선암 환자에 대한 일차 치료로서 화학요법과 병용하여 피하 주사로 투여되는 티슬렐리주맙을 정맥 내 주입 대비 비교하는 제3상, 다기관, 무작위배정, 공개 임상시험
A12: 8 | B12: 모집중 | C12: =IF(B12="종료","종료","진행중") -> 진행중 | D12: 45868 | E12: BGB-16673 | F12: BTK CDAC | G12: 혈액암 | H12: 3상 | I12: R/R CLL/SLL vs pirtobrutinib | J12: BGB-16673-304 (CaDAnCe-304) | K12: NCT06973187 | L12: Enrolling | M12: Ph3 304 R/R CLL (vs. Pirto) | N12: 매칭 | O12: 일치 | Q12: =실시기관!I38 -> 6 | R12: 경상국립대병원, 분당서울대병원, 부산대병원, 서울성모병원, 서울대병원, 세브란스병원 | S12: 재발성/불응성 만성 림프구성 백혈병 또는 소림프구성 림프종 환자에서 퍼토브루티닙과 비교하여 BGB-16673의 안전성 및 유효성을 평가하는 제3상, 공개, 무작위배정 시험
A13: 9 | B13: 모집중 | C13: =IF(B13="종료","종료","진행중") -> 진행중 | D13: 45841 | E13: BGB-16673 | F13: BTK CDAC | G13: 혈액암 | H13: 3상 | I13: BTKi·BCL2i 모두 경치료한 CLL/SLL vs 연구자 선택(IdelaR / BR / VenR) | J13: BGB-16673-302 (CaDAnCe-302) | K13: NCT06846671 | L13: Enrolling | M13: Ph3 302 R/R CLL | N13: 매칭 | O13: 일치 | Q13: =실시기관!J38 -> 9 | R13: 경상국립대병원, 여의도성모병원, 서울대병원, 경북대병원, 서울성모병원, 삼성서울병원, 화순전남대병원, 동아대병원, 국립암센터 | S13: 이전에 BTK 억제제와 BCL2 억제제에 모두 노출된 만성 림프구성 백혈병 또는 소림프구성 림프종이 있는 환자에서 BGB-16673과 시험자 선택 요법 (이델라리십 + 리툭시맙 또는 벤다무스틴 + 리툭시맙 또는 베네토클락스 + 리툭시맙 재투여)을 비교하는 제3상, 라벨 공개, 무작위 배정 임상시험
A14: 10 | B14: 종료 | C14: =IF(B14="종료","종료","진행중") -> 종료 | D14: 45828 | E14: BGB-53038, 티슬렐리주맙(BGB-A317) | F14: pan-KRAS 억제제 | G14: 고형암 | H14: 1상 | I14: KRAS 변이·증폭 진행성 고형암, 단독·병용 1a/1b | M14: 미표기 | N14: 미수록 | O14: 정합 | P14: 파이프라인에서 제외된 과제 (국내 종료와 일치) | Q14: =실시기관!K38 -> 5 | R14: 서울대병원, 서울아산병원, 삼성서울병원, 세브란스병원, 분당서울대병원 | S14: KRAS 돌연변이 또는 증폭이 있는 진행성 또는 전이성 고형 종양이 있는 환자에서 단독 요법 또는 병용 요법으로 범-KRAS 억제제인 BGB-53038의 안전성, 내약성, 약동학, 약력학 및 예비 항종양 활성을 조사하기 위한 제1a/1b상 임상시험
A15: 11 | B15: 모집중 | C15: =IF(B15="종료","종료","진행중") -> 진행중 | D15: 45797 | E15: BGB-11417(손로토클락스) | F15: BCL2i | G15: 혈액암 | H15: 3상 | I15: R/R CLL/SLL, sonro+anti-CD20 vs VenR | J15: BGB-11417-303 (CELESTIAL-RRCLL) | K15: NCT06943872 | L15: Enrolling | M15: Ph3 303 R/R CLL | N15: 매칭 | O15: 일치 | Q15: =실시기관!L38 -> 7 | R15: 서울대병원, 국립암센터, 분당서울대병원, 부산대병원, 세브란스병원, 서울성모병원, 삼성서울병원 | S15: 재발성/불응성 만성 림프구성 백혈병/소림프구성 림프종 환자에서 손로토클락스 + 항-CD20 항체 요법과 베네토클락스 + 리툭시맙을 비교하는 제3상, 무작위 배정, 라벨 공개, 다기관 임상시험
A16: 12 | B16: 종료 | C16: =IF(B16="종료","종료","진행중") -> 종료 | D16: 45761 | E16: 티슬렐리주맙(BGB-A317), BGB-A3055 | F16: – | G16: 고형암 | H16: 1상 | I16: 선별된 진행성·전이성 고형암, 단독·tislelizumab 병용 1a/1b | M16: 미표기 | N16: 미수록 | O16: 정합 | P16: 파이프라인에서 제외된 과제 (국내 종료와 일치) | Q16: =실시기관!M38 -> 5 | R16: 삼성서울병원, 서울아산병원, 분당서울대병원, 서울대병원, 세브란스병원 | S16: 선별된 진행성 또는 전이성 고형 종양이 있는 환자에서 BGB-A3055 단독 요법 및 티슬렐리주맙과 병용 요법의 안전성, 내약성, 약동학, 약력학 및 예비 항종양 활성을 조사하기 위한 제1a/1b상 임상시험
A17: 13 | B17: 종료 | C17: =IF(B17="종료","종료","진행중") -> 종료 | D17: 45743 | E17: BG-60366 | F17: EGFR CDAC | G17: 고형암 | H17: 1상 | I17: EGFR 변이 NSCLC 1a/1b | M17: 미표기 | N17: 미수록 | O17: 정합 | P17: 파이프라인에서 제외된 과제 (국내 종료와 일치) | Q17: =실시기관!N38 -> 4 | R17: 충북대병원, 삼성서울병원, 서울대병원, 세브란스병원 | S17: EGFR-돌연변이 비소세포 폐암 환자를 대상으로 EGFR 분해 CDAC인 BG-60366의 안전성, 내약성, 약물동태, 약물동력, 항종양 활성을 조사하는 제1a/1b상 공개 임상시험
A18: 14 | B18: 종료 | C18: =IF(B18="종료","종료","진행중") -> 종료 | D18: 45720 | E18: BG-68501/BGB-43395 | F18: CDK2i | G18: 고형암 | H18: 1상 | I18: 진행성 고형암 1a/1b | J18: BG-68501-101 | K18: NCT06257264 | L18: Closeout | M18: 미표기 | N18: 매칭 | O18: 정합 | P18: CDK2 전략은 BG-75098(CDK2 CDAC, No.2)로 넘어감 | Q18: =실시기관!O38 -> 6 | R18: 국립암센터, 분당서울대병원, 삼성서울병원, 서울아산병원, 세브란스병원, 서울대병원 | S18: 진행성 고형 종양이 있는 참가자 대상의 선택적 CDK2 억제제 BG-68501의 제 1a/1b상 임상시험
A19: 15 | B19: 모집중 | C19: =IF(B19="종료","종료","진행중") -> 진행중 | D19: 45681 | E19: BGB-11417(손로토클락스) | F19: BCL2i | G19: 혈액암 | H19: 3상 | I19: R/R MCL, sonro+zanu vs 위약+zanu, 이중눈가림 | J19: BGB-11417-302 (CELESTIAL-RRMCL) | K19: NCT06742996 | L19: Enrolling | M19: Ph3 302 R/R MCL | N19: 매칭 | O19: 일치 | Q19: =실시기관!P38 -> 8 | R19: 여의도성모병원, 분당서울대병원, 부산대병원, 서울성모병원, 삼성서울병원, 서울아산병원, 세브란스병원, 서울대병원 | S19: 재발성/불응성 외투 세포 림프종 환자를 대상으로 한 손로토클락스+자누브루티닙 대 위약+자누브루티닙의 무작위배정, 이중눈가림, 다기관 제3상 임상시험
A20: 16 | B20: 모집중 | C20: =IF(B20="종료","종료","진행중") -> 진행중 | D20: 45664 | E20: BGB-58067, 티슬렐리주맙(BGB-A317) | F20: MTA-coop PRMT5i | G20: 고형암 | H20: 1상 | I20: 진행성 고형암, 단독·항암제 병용 1a/b | J20: BGB-58067-101 | K20: NCT06589596 | L20: Dose Escalation | M20: Ph1 101 Solid tumors | N20: 매칭 | O20: 일치 | Q20: =실시기관!Q38 -> 6 | R20: 분당서울대병원, 삼성서울병원, 성빈센트병원, 서울대병원, 서울아산병원, 세브란스병원 | S20: 진행성 고형 종양 환자를 대상으로 PRMT5 억제제인 BGB-58067 단독요법 및 항암제와 병용요법의 안전성, 내약성, 약동학, 약력학 및 예비 항종양 활성을 조사하는 제 1a/b 상 시험
A21: 17 | B21: 종료 | C21: =IF(B21="종료","종료","진행중") -> 종료 | D21: 45660 | E21: BG-C137/BGB-A317(티슬렐리주맙) | F21: FGFR2b ADC | G21: 고형암 | H21: 1상 | I21: 진행성 고형암 1a/b | J21: BG-C137-101 | K21: NCT06625593 | L21: Dose Escalation | M21: Ph1 101 Solid tumors (진행 중) | N21: 매칭 | O21: 확인 필요 | P21: 글로벌은 진행 중인데 국내는 '종료'. 한국 사이트만 종료(국가 철수)했는지 확인 필요 | Q21: =실시기관!R38 -> 10 | R21: 성빈센트병원, 분당차병원, 칠곡경북대병원, 길병원, 강남세브란스병원, 삼성서울병원, 세브란스병원, 서울대병원, 분당서울대병원, 서울아산병원 | S21: 진행성 고형종양 환자에서 FGFR2b를 표적으로 하는 항체-약물 접합체인 BG-C137의 안전성, 내약성, 약동학, 약력학 및 예비 항종양 활성을 조사하기 위한 1a/b상, 공개, 다기관 시험
A22: 18 | B22: 모집중 | C22: =IF(B22="종료","종료","진행중") -> 진행중 | D22: 45555 | E22: BGB-43395 | F22: CDK4i | G22: 고형암 | H22: 1상 | I22: 전이성 HR+/HER2- 유방암 및 진행성 고형암, 단독·병용 1a/1b | J22: BGB-43395-101 | K22: NCT06120283 | L22: Dose Expansion | M22: Ph1 101 Solid tumors | N22: 매칭 | O22: 일치 | Q22: =실시기관!S38 -> 8 | R22: 서울대병원, 서울성모병원, 고대안암병원, 분당서울대병원, 길병원, 삼성서울병원, 서울아산병원, 세브란스병원 | S22: 전이성 HR+/HER2- 유방암 및 기타 진행성 고형종양 환자를 대상으로 단독으로 또는 병합요법의 일부로 투여되는 CDK4 억제제 BGB-43395의 안전성과 내약성, 약동학, 약력학, 예비 항종양 활성을 조사하는 제1a/1b상 임상시험
A23: 19 | B23: 모집중 | C23: =IF(B23="종료","종료","진행중") -> 진행중 | D23: 45554 | E23: BGB-B2033/티슬렐리주맙(BGB-A317) | F23: GPC3×4-1BB bsAb | G23: 고형암 | H23: 1상 | I23: 선택된 진행성·전이성 고형암, 단독 또는 tislelizumab ± bevacizumab 병용 | J23: BGB-B2033-101 | K23: NCT06427941 | L23: Dose Escalation | M23: Ph1 101 Solid tumors / Ph2 101 3L+ HCC | N23: 매칭 | O23: 일치 | P23: Appendix 표는 Ph1, 자산 목록은 Ph1/2로 표기 | Q23: =실시기관!T38 -> 7 | R23: 서울아산병원, 충북대병원, 삼성서울병원, 분당서울대병원, 서울대병원, 세브란스병원, 분당차병원 | S23: 선택된 특정 진행성 또는 전이성 고형종양 참가자를 대상으로 단독으로 또는 Tislelizumab ± Bevacizumab과의 병합요법으로 투여되는 BGB-B2033의 안전성과 내약성, 약동학, 약력학, 예비 항종양 활성을 조사하는 제1상 임상시험
A24: 20 | B24: 모집완료 | C24: =IF(B24="종료","종료","진행중") -> 진행중 | D24: 45266 | E24: BGB-11417(손로토클락스) | F24: BCL2i | G24: 혈액암 | H24: 3상 | I24: TN CLL, sonro+zanu vs VenO | J24: BGB-11417-301 (CELESTIAL-TNCLL) | K24: NCT06073821 | L24: Maintenance | M24: Ph3 301 TN CLL | N24: 매칭 | O24: 일치 | P24: 모집 종료 후 추적 단계 | Q24: =실시기관!U38 -> 9 | R24: 국립암센터, 분당서울대병원, 부산대병원, 화순전남대병원, 서울성모병원, 삼성서울병원, 서울아산병원, 세브란스병원, 서울대병원 | S24: 이전에 치료받지 않은 만성 림프구성 백혈병 환자를 대상으로 손로토클락스(BGB-11417)와 자누브루티닙(BGB-3111)의 병용요법을 베네토클락스와 오비누투주맙의 병용요법과 비교하는 제3상, 공개, 무작위배정 임상시험
A25: 21 | B25: 종료 | C25: =IF(B25="종료","종료","진행중") -> 종료 | D25: 45253 | E25: BGB-A445, BGB-15025 | F25: OX40 mAb + HPK1i | G25: 고형암 | H25: 2상 | I25: anti-PD-(L)1 경치료 NSCLC, 무작위 다중군 | M25: 미표기 | N25: 미수록 | O25: 정합 | P25: Appendix 미수록. ClinicalTrials.gov 기준 BGB-LC-203 (NCT06029127), Completed | Q25: =실시기관!V38 -> 10 | R25: 분당차병원, 경상국립대병원, 충북대병원, 삼성서울병원, 서울아산병원, 성빈센트병원, 길병원, 서울대병원, 국립암센터, 세브란스병원 | S25: 이전에 항PD-(L)1 항체로 치료받은 비소세포폐암 환자에서 BGB-A445를 임상시험용 제제와 병용하는 제2상, 공개, 무작위배정, 다중군 임상시험
A27: 판정 기준: nedrug '모집중·승인완료' ↔ Appendix 'Enrolling·Dose Escalation/Expansion', '모집완료' ↔ 'Maintenance', '종료' ↔ 'Closeout' 또는 파이프라인 제외.
A28: 진행 구분은 국내 상태가 '종료'가 아닌 시험을 '진행중'으로 분류하는 수식임 (모집중·승인완료·모집완료 포함).
A29: MOA·치료영역·대상 요약·판정·비고는 nedrug 원문과 Appendix를 대조해 작성자가 정리한 값임. 국내 실시기관 수는 '실시기관' 시트의 수식을 참조함.
A30: Source: BeOne_nedrug_20261013_임상시험정보검색.xlsx · Q2_2026_earnings_-_Clinical_Trials_Appendix_-_FINAL.pdf (p.12–22) · BeOne-website-pipeline-Aug-2026.pdf · No.21: clinicaltrials.gov/study/NCT06029127

Sheet 실시기관
A1: 국내 실시기관 × 시험 매트릭스
A2: 1 = 해당 시험 참여 (nedrug 실시기관, 기관명 표준화·중복 제거). 참여 수는 수식으로 계산
A4: 시험 No | B4: =시험별비교!A5 -> 1 | C4: =시험별비교!A6 -> 2 | D4: =시험별비교!A7 -> 3 | E4: =시험별비교!A8 -> 4 | F4: =시험별비교!A9 -> 5 | G4: =시험별비교!A10 -> 6 | H4: =시험별비교!A11 -> 7 | I4: =시험별비교!A12 -> 8 | J4: =시험별비교!A13 -> 9 | K4: =시험별비교!A14 -> 10 | L4: =시험별비교!A15 -> 11 | M4: =시험별비교!A16 -> 12 | N4: =시험별비교!A17 -> 13 | O4: =시험별비교!A18 -> 14 | P4: =시험별비교!A19 -> 15 | Q4: =시험별비교!A20 -> 16 | R4: =시험별비교!A21 -> 17 | S4: =시험별비교!A22 -> 18 | T4: =시험별비교!A23 -> 19 | U4: =시험별비교!A24 -> 20 | V4: =시험별비교!A25 -> 21 | W4: 진행중 시험 참여 수 | X4: 전체 시험 참여 수
A5: 제품 | B5: =시험별비교!E5 -> BG-C477 | C5: =시험별비교!E6 -> BG-75098, BGB-43395 | D5: =시험별비교!E7 -> BG-C477 | E5: =시험별비교!E8 -> BGB-43395 | F5: =시험별비교!E9 -> BGB-11417(손로토클락스) | G5: =시험별비교!E10 -> BG-T187 | H5: =시험별비교!E11 -> 티슬렐리주맙(BGB-A317) | I5: =시험별비교!E12 -> BGB-16673 | J5: =시험별비교!E13 -> BGB-16673 | K5: =시험별비교!E14 -> BGB-53038, 티슬렐리주맙(BGB-A317) | L5: =시험별비교!E15 -> BGB-11417(손로토클락스) | M5: =시험별비교!E16 -> 티슬렐리주맙(BGB-A317), BGB-A3055 | N5: =시험별비교!E17 -> BG-60366 | O5: =시험별비교!E18 -> BG-68501/BGB-43395 | P5: =시험별비교!E19 -> BGB-11417(손로토클락스) | Q5: =시험별비교!E20 -> BGB-58067, 티슬렐리주맙(BGB-A317) | R5: =시험별비교!E21 -> BG-C137/BGB-A317(티슬렐리주맙) | S5: =시험별비교!E22 -> BGB-43395 | T5: =시험별비교!E23 -> BGB-B2033/티슬렐리주맙(BGB-A317) | U5: =시험별비교!E24 -> BGB-11417(손로토클락스) | V5: =시험별비교!E25 -> BGB-A445, BGB-15025
A6: 단계 | B6: =시험별비교!H5 -> 2상 | C6: =시험별비교!H6 -> 1상 | D6: =시험별비교!H7 -> 1상 | E6: =시험별비교!H8 -> 3상 | F6: =시험별비교!H9 -> 3상 | G6: =시험별비교!H10 -> 1상 | H6: =시험별비교!H11 -> 3상 | I6: =시험별비교!H12 -> 3상 | J6: =시험별비교!H13 -> 3상 | K6: =시험별비교!H14 -> 1상 | L6: =시험별비교!H15 -> 3상 | M6: =시험별비교!H16 -> 1상 | N6: =시험별비교!H17 -> 1상 | O6: =시험별비교!H18 -> 1상 | P6: =시험별비교!H19 -> 3상 | Q6: =시험별비교!H20 -> 1상 | R6: =시험별비교!H21 -> 1상 | S6: =시험별비교!H22 -> 1상 | T6: =시험별비교!H23 -> 1상 | U6: =시험별비교!H24 -> 3상 | V6: =시험별비교!H25 -> 2상
A7: 진행 구분 | B7: =시험별비교!C5 -> 진행중 | C7: =시험별비교!C6 -> 진행중 | D7: =시험별비교!C7 -> 진행중 | E7: =시험별비교!C8 -> 진행중 | F7: =시험별비교!C9 -> 진행중 | G7: =시험별비교!C10 -> 진행중 | H7: =시험별비교!C11 -> 진행중 | I7: =시험별비교!C12 -> 진행중 | J7: =시험별비교!C13 -> 진행중 | K7: =시험별비교!C14 -> 종료 | L7: =시험별비교!C15 -> 진행중 | M7: =시험별비교!C16 -> 종료 | N7: =시험별비교!C17 -> 종료 | O7: =시험별비교!C18 -> 종료 | P7: =시험별비교!C19 -> 진행중 | Q7: =시험별비교!C20 -> 진행중 | R7: =시험별비교!C21 -> 종료 | S7: =시험별비교!C22 -> 진행중 | T7: =시험별비교!C23 -> 진행중 | U7: =시험별비교!C24 -> 진행중 | V7: =시험별비교!C25 -> 종료
A8: 서울대병원 | B8: 1 | C8: 1 | E8: 1 | F8: 1 | G8: 1 | H8: 1 | I8: 1 | J8: 1 | K8: 1 | L8: 1 | M8: 1 | N8: 1 | O8: 1 | P8: 1 | Q8: 1 | R8: 1 | S8: 1 | T8: 1 | U8: 1 | V8: 1 | W8: =SUMPRODUCT(($B$7:$V$7="진행중")*(B8:V8)) -> 14 | X8: =SUM(B8:V8) -> 20
A9: 세브란스병원 | B9: 1 | C9: 1 | D9: 1 | E9: 1 | F9: 1 | G9: 1 | H9: 1 | I9: 1 | K9: 1 | L9: 1 | M9: 1 | N9: 1 | O9: 1 | P9: 1 | Q9: 1 | R9: 1 | S9: 1 | T9: 1 | U9: 1 | V9: 1 | W9: =SUMPRODUCT(($B$7:$V$7="진행중")*(B9:V9)) -> 14 | X9: =SUM(B9:V9) -> 20
A10: 삼성서울병원 | B10: 1 | C10: 1 | D10: 1 | E10: 1 | G10: 1 | H10: 1 | J10: 1 | K10: 1 | L10: 1 | M10: 1 | N10: 1 | O10: 1 | P10: 1 | Q10: 1 | R10: 1 | S10: 1 | T10: 1 | U10: 1 | V10: 1 | W10: =SUMPRODUCT(($B$7:$V$7="진행중")*(B10:V10)) -> 13 | X10: =SUM(B10:V10) -> 19
A11: 분당서울대병원 | B11: 1 | D11: 1 | E11: 1 | F11: 1 | G11: 1 | H11: 1 | I11: 1 | K11: 1 | L11: 1 | M11: 1 | O11: 1 | P11: 1 | Q11: 1 | R11: 1 | S11: 1 | T11: 1 | U11: 1 | W11: =SUMPRODUCT(($B$7:$V$7="진행중")*(B11:V11)) -> 13 | X11: =SUM(B11:V11) -> 17
A12: 서울아산병원 | B12: 1 | C12: 1 | D12: 1 | E12: 1 | F12: 1 | G12: 1 | H12: 1 | K12: 1 | M12: 1 | O12: 1 | P12: 1 | Q12: 1 | R12: 1 | S12: 1 | T12: 1 | U12: 1 | V12: 1 | W12: =SUMPRODUCT(($B$7:$V$7="진행중")*(B12:V12)) -> 12 | X12: =SUM(B12:V12) -> 17
A13: 서울성모병원 | E13: 1 | F13: 1 | G13: 1 | I13: 1 | J13: 1 | L13: 1 | P13: 1 | S13: 1 | U13: 1 | W13: =SUMPRODUCT(($B$7:$V$7="진행중")*(B13:V13)) -> 9 | X13: =SUM(B13:V13) -> 9
A14: 국립암센터 | B14: 1 | C14: 1 | E14: 1 | J14: 1 | L14: 1 | O14: 1 | U14: 1 | V14: 1 | W14: =SUMPRODUCT(($B$7:$V$7="진행중")*(B14:V14)) -> 6 | X14: =SUM(B14:V14) -> 8
A15: 부산대병원 | I15: 1 | L15: 1 | P15: 1 | U15: 1 | W15: =SUMPRODUCT(($B$7:$V$7="진행중")*(B15:V15)) -> 4 | X15: =SUM(B15:V15) -> 4
A16: 성빈센트병원 | E16: 1 | G16: 1 | Q16: 1 | R16: 1 | V16: 1 | W16: =SUMPRODUCT(($B$7:$V$7="진행중")*(B16:V16)) -> 3 | X16: =SUM(B16:V16) -> 5
A17: 화순전남대병원 | E17: 1 | J17: 1 | U17: 1 | W17: =SUMPRODUCT(($B$7:$V$7="진행중")*(B17:V17)) -> 3 | X17: =SUM(B17:V17) -> 3
A18: 길병원 | E18: 1 | R18: 1 | S18: 1 | V18: 1 | W18: =SUMPRODUCT(($B$7:$V$7="진행중")*(B18:V18)) -> 2 | X18: =SUM(B18:V18) -> 4
A19: 분당차병원 | E19: 1 | R19: 1 | T19: 1 | V19: 1 | W19: =SUMPRODUCT(($B$7:$V$7="진행중")*(B19:V19)) -> 2 | X19: =SUM(B19:V19) -> 4
A20: 충북대병원 | E20: 1 | N20: 1 | T20: 1 | V20: 1 | W20: =SUMPRODUCT(($B$7:$V$7="진행중")*(B20:V20)) -> 2 | X20: =SUM(B20:V20) -> 4
A21: 경상국립대병원 | I21: 1 | J21: 1 | V21: 1 | W21: =SUMPRODUCT(($B$7:$V$7="진행중")*(B21:V21)) -> 2 | X21: =SUM(B21:V21) -> 3
A22: 고대안암병원 | E22: 1 | S22: 1 | W22: =SUMPRODUCT(($B$7:$V$7="진행중")*(B22:V22)) -> 2 | X22: =SUM(B22:V22) -> 2
A23: 동아대병원 | E23: 1 | J23: 1 | W23: =SUMPRODUCT(($B$7:$V$7="진행중")*(B23:V23)) -> 2 | X23: =SUM(B23:V23) -> 2
A24: 여의도성모병원 | J24: 1 | P24: 1 | W24: =SUMPRODUCT(($B$7:$V$7="진행중")*(B24:V24)) -> 2 | X24: =SUM(B24:V24) -> 2
A25: 강남세브란스병원 | E25: 1 | R25: 1 | W25: =SUMPRODUCT(($B$7:$V$7="진행중")*(B25:V25)) -> 1 | X25: =SUM(B25:V25) -> 2
A26: 칠곡경북대병원 | H26: 1 | R26: 1 | W26: =SUMPRODUCT(($B$7:$V$7="진행중")*(B26:V26)) -> 1 | X26: =SUM(B26:V26) -> 2
A27: 경북대병원 | J27: 1 | W27: =SUMPRODUCT(($B$7:$V$7="진행중")*(B27:V27)) -> 1 | X27: =SUM(B27:V27) -> 1
A28: 계명대동산병원 | E28: 1 | W28: =SUMPRODUCT(($B$7:$V$7="진행중")*(B28:V28)) -> 1 | X28: =SUM(B28:V28) -> 1
A29: 고대구로병원 | E29: 1 | W29: =SUMPRODUCT(($B$7:$V$7="진행중")*(B29:V29)) -> 1 | X29: =SUM(B29:V29) -> 1
A30: 고대안산병원 | E30: 1 | W30: =SUMPRODUCT(($B$7:$V$7="진행중")*(B30:V30)) -> 1 | X30: =SUM(B30:V30) -> 1
A31: 순천향대천안병원 | E31: 1 | W31: =SUMPRODUCT(($B$7:$V$7="진행중")*(B31:V31)) -> 1 | X31: =SUM(B31:V31) -> 1
A32: 아주대병원 | E32: 1 | W32: =SUMPRODUCT(($B$7:$V$7="진행중")*(B32:V32)) -> 1 | X32: =SUM(B32:V32) -> 1
A33: 울산대병원 | E33: 1 | W33: =SUMPRODUCT(($B$7:$V$7="진행중")*(B33:V33)) -> 1 | X33: =SUM(B33:V33) -> 1
A34: 이대목동병원 | E34: 1 | W34: =SUMPRODUCT(($B$7:$V$7="진행중")*(B34:V34)) -> 1 | X34: =SUM(B34:V34) -> 1
A35: 인하대병원 | E35: 1 | W35: =SUMPRODUCT(($B$7:$V$7="진행중")*(B35:V35)) -> 1 | X35: =SUM(B35:V35) -> 1
A36: 중앙대병원 | E36: 1 | W36: =SUMPRODUCT(($B$7:$V$7="진행중")*(B36:V36)) -> 1 | X36: =SUM(B36:V36) -> 1
A37: 해운대백병원 | E37: 1 | W37: =SUMPRODUCT(($B$7:$V$7="진행중")*(B37:V37)) -> 1 | X37: =SUM(B37:V37) -> 1
A38: 기관 수 (시험별) | B38: =SUM(B8:B37) -> 6 | C38: =SUM(C8:C37) -> 5 | D38: =SUM(D8:D37) -> 4 | E38: =SUM(E8:E37) -> 25 | F38: =SUM(F8:F37) -> 5 | G38: =SUM(G8:G37) -> 7 | H38: =SUM(H8:H37) -> 6 | I38: =SUM(I8:I37) -> 6 | ... V38: =SUM(V8:V37) -> 10
A40: 기관명은 nedrug 원문을 표준화한 것임 (예: '재단법인아산사회복지재단서울아산병원' → 서울아산병원). nedrug 원문에 같은 기관이 두 번 들어간 행(No.6·16·19의 삼성서울병원, No.2의 세브란스병원)은 1회로 셈.
A41: 파란 칸 = 진행 중 시험 참여, 회색 칸 = 종료 시험 참여.
A42: Source: BeOne_nedrug_20261013_임상시험정보검색.xlsx '실시기관' 열

Sheet Appendix전체대조
A1: Appendix 전체 시험 목록 × 국내 등재 여부
A2: Q2 2026 Clinical Trial Appendix p.12–22 (As of 2026-07-24) 전체 시험 86건. 국내 nedrug No가 있으면 국내 상태를 수식으로 불러옴
A4: Appendix 페이지 | B4: 치료영역 | C4: 자산 | D4: MOA | E4: 시험 (프로토콜) | F4: 별칭 | G4: 단계 | H4: NCT | I4: 대상 (Population) | J4: 대상자 수 | K4: 대상자 수 비고 | L4: 병용 약물 | M4: 1차 평가변수 | N4: Appendix 상태 | O4: 상태 구분 | P4: 국내 nedrug No | Q4: 국내 상태 (nedrug) | R4: 비고
A5: 12 | B5: 혈액암 | C5: Zanubrutinib | D5: BTKi | E5: BGB-3111-304 | F5: SEQUOIA | G5: Ph3 | H5: NCT03336333 | I5: TN CLL/SLL | J5: 784 | L5: Venetoclax (arm D) | M5: PFS | N5: Approved / Maint. (arm D) | O5: =IF(ISNUMBER(SEARCH("Approved",N5)),"승인",IF(N5="Closeout","종료",IF(N5="Maintenance","유지","진행"))) -> 승인 | Q5: =IF(P5="","",INDEX(시험별비교!$B$5:$B$25,MATCH(P5,시험별비교!$A$5:$A$25,0)))
A6: 12 | B6: 혈액암 | C6: Zanubrutinib | D6: BTKi | E6: BGB-3111-306 | F6: MANGROVE | G6: Ph3 | H6: NCT04002297 | I6: TN MCL | J6: 510 | L6: Rituximab | M6: PFS | N6: Maintenance | O6: =IF(ISNUMBER(SEARCH("Approved",N6)),"승인",IF(N6="Closeout","종료",IF(N6="Maintenance","유지","진행"))) -> 유지 | Q6: =IF(P6="","",INDEX(시험별비교!$B$5:$B$25,MATCH(P6,시험별비교!$A$5:$A$25,0)))
A7: 12 | B7: 혈액암 | C7: Zanubrutinib | D7: BTKi | E7: BGB-3111-308 | F7: MAHOGANY | G7: Ph3 | H7: NCT05100862 | I7: R/R MZL and FL | J7: 799 | L7: Rituximab, Obinutuzumab | M7: PFS | N7: Maintenance | O7: =IF(ISNUMBER(SEARCH("Approved",N7)),"승인",IF(N7="Closeout","종료",IF(N7="Maintenance","유지","진행"))) -> 유지 | Q7: =IF(P7="","",INDEX(시험별비교!$B$5:$B$25,MATCH(P7,시험별비교!$A$5:$A$25,0)))
A8: 12 | B8: 혈액암 | C8: Zanubrutinib | D8: BTKi | E8: BGB-3111-LTE1 | G8: Ph3 | H8: NCT04170283 | I8: B-Cell Malignancies | J8: 956 | M8: TEAEs | N8: Maintenance | O8: =IF(ISNUMBER(SEARCH("Approved",N8)),"승인",IF(N8="Closeout","종료",IF(N8="Maintenance","유지","진행"))) -> 유지 | Q8: =IF(P8="","",INDEX(시험별비교!$B$5:$B$25,MATCH(P8,시험별비교!$A$5:$A$25,0)))
A9: 12 | B9: 혈액암 | C9: Zanubrutinib | D9: BTKi | E9: BGB-3111-114 | G9: Ph1 | H9: NCT05767398 | I9: Healthy volunteers | J9: 58 | L9: - | M9: PK | N9: Approved | O9: =IF(ISNUMBER(SEARCH("Approved",N9)),"승인",IF(N9="Closeout","종료",IF(N9="Maintenance","유지","진행"))) -> 승인 | Q9: =IF(P9="","",INDEX(시험별비교!$B$5:$B$25,MATCH(P9,시험별비교!$A$5:$A$25,0))) | R9: 정제 제형. 국내는 80mg 캡슐만 허가됨
A10: 12 | B10: 혈액암 | C10: Zanubrutinib | D10: BTKi | E10: BGB-3111-206 | G10: Ph2 | H10: NCT03206970 | I10: R/R MCL | J10: 86 | L10: - | M10: ORR | N10: Approved | O10: =IF(ISNUMBER(SEARCH("Approved",N10)),"승인",IF(N10="Closeout","종료",IF(N10="Maintenance","유지","진행"))) -> 승인 | Q10: =IF(P10="","",INDEX(시험별비교!$B$5:$B$25,MATCH(P10,시험별비교!$A$5:$A$25,0)))
A11: 12 | B11: 혈액암 | C11: Zanubrutinib | D11: BTKi | E11: BGB-3111-212 | F11: ROSEWOOD | G11: Ph2 | H11: NCT03332017 | I11: R/R FL | J11: 217 | L11: Obinutuzumab | M11: ORR | N11: Approved | O11: =IF(ISNUMBER(SEARCH("Approved",N11)),"승인",IF(N11="Closeout","종료",IF(N11="Maintenance","유지","진행"))) -> 승인 | Q11: =IF(P11="","",INDEX(시험별비교!$B$5:$B$25,MATCH(P11,시험별비교!$A$5:$A$25,0)))
A12: 12 | B12: 혈액암 | C12: Zanubrutinib | D12: BTKi | E12: BGB-3111-214 | F12: MAGNOLIA | G12: Ph2 | H12: NCT03846427 | I12: R/R MZL | J12: 68 | L12: - | M12: ORR | N12: Approved | O12: =IF(ISNUMBER(SEARCH("Approved",N12)),"승인",IF(N12="Closeout","종료",IF(N12="Maintenance","유지","진행"))) -> 승인 | Q12: =IF(P12="","",INDEX(시험별비교!$B$5:$B$25,MATCH(P12,시험별비교!$A$5:$A$25,0)))
A13: 12 | B13: 혈액암 | C13: Zanubrutinib | D13: BTKi | E13: BGB-3111-302 | F13: ASPEN | G13: Ph3 | H13: NCT03053440 | I13: TN and R/R WM | J13: 229 | L13: - | M13: CR\VGPR | N13: Approved | O13: =IF(ISNUMBER(SEARCH("Approved",N13)),"승인",IF(N13="Closeout","종료",IF(N13="Maintenance","유지","진행"))) -> 승인 | Q13: =IF(P13="","",INDEX(시험별비교!$B$5:$B$25,MATCH(P13,시험별비교!$A$5:$A$25,0)))
A14: 12 | B14: 혈액암 | C14: Zanubrutinib | D14: BTKi | E14: BGB-3111-305 | F14: ALPINE | G14: Ph3 | H14: NCT03734016 | I14: R/R CLL | J14: 652 | L14: - | M14: ORR | N14: Approved | O14: =IF(ISNUMBER(SEARCH("Approved",N14)),"승인",IF(N14="Closeout","종료",IF(N14="Maintenance","유지","진행"))) -> 승인 | Q14: =IF(P14="","",INDEX(시험별비교!$B$5:$B$25,MATCH(P14,시험별비교!$A$5:$A$25,0)))
A15: 13 | B15: 혈액암 | C15: Sonrotoclax | D15: BCL2i | E15: BGB-11417-101 | G15: Ph1 | H15: NCT04277637 | I15: B-Cell Malignancies & NHL | J15: 437 | L15: Zanubrutinib, Obinutuzumab | M15: TEAEs, MTD | N15: Maintenance | O15: =IF(ISNUMBER(SEARCH("Approved",N15)),"승인",IF(N15="Closeout","종료",IF(N15="Maintenance","유지","진행"))) -> 유지 | Q15: =IF(P15="","",INDEX(시험별비교!$B$5:$B$25,MATCH(P15,시험별비교!$A$5:$A$25,0)))
A16: 13 | B16: 혈액암 | C16: Sonrotoclax | D16: BCL2i | E16: BGB-11417-102 | G16: Ph1 | H16: NCT04883957 | I16: B-Cell Malignancies | J16: 64 | K16: 중국 등록 | L16: - | M16: TEAEs, MTD | N16: Maintenance | O16: =IF(ISNUMBER(SEARCH("Approved",N16)),"승인",IF(N16="Closeout","종료",IF(N16="Maintenance","유지","진행"))) -> 유지 | Q16: =IF(P16="","",INDEX(시험별비교!$B$5:$B$25,MATCH(P16,시험별비교!$A$5:$A$25,0))) | R16: 중국 시험
A17: 13 | B17: 혈액암 | C17: Sonrotoclax | D17: BCL2i | E17: BGB-11417-103 | G17: Ph1/2 | H17: NCT04771130 | I17: AML/MDS | J17: 260 | L17: Azacitidine | M17: TEAEs, CR, mOR | N17: Enrolling | O17: =IF(ISNUMBER(SEARCH("Approved",N17)),"승인",IF(N17="Closeout","종료",IF(N17="Maintenance","유지","진행"))) -> 진행 | Q17: =IF(P17="","",INDEX(시험별비교!$B$5:$B$25,MATCH(P17,시험별비교!$A$5:$A$25,0)))
A18: 13 | B18: 혈액암 | C18: Sonrotoclax | D18: BCL2i | E18: BGB-11417-105 | G18: Ph1/2 | H18: NCT04973605 | I18: R/R MM with t(11;14) | J18: 246 | L18: Dexamethasone, Carfilzomib, Daratumumab, Pomalidomide | M18: TEAEs, ORR, VGPR, CR | N18: Enrolling | O18: =IF(ISNUMBER(SEARCH("Approved",N18)),"승인",IF(N18="Closeout","종료",IF(N18="Maintenance","유지","진행"))) -> 진행 | Q18: =IF(P18="","",INDEX(시험별비교!$B$5:$B$25,MATCH(P18,시험별비교!$A$5:$A$25,0)))
A19: 13 | B19: 혈액암 | C19: Sonrotoclax | D19: BCL2i | E19: BGB-11417-108 | G19: Ph1/2 | H19: NCT06697184 | I19: B-Cell Malignancies | J19: 258 | L19: Zanubrutinib | M19: TLS | N19: Enrolling | O19: =IF(ISNUMBER(SEARCH("Approved",N19)),"승인",IF(N19="Closeout","종료",IF(N19="Maintenance","유지","진행"))) -> 진행 | Q19: =IF(P19="","",INDEX(시험별비교!$B$5:$B$25,MATCH(P19,시험별비교!$A$5:$A$25,0)))
A20: 13 | B20: 혈액암 | C20: Sonrotoclax | D20: BCL2i | E20: BGB-11417-203 | G20: Ph2 | H20: NCT05952037 | I20: R/R WM | J20: 114 | L20: Zanubrutinib | M20: MRR | N20: Maintenance | O20: =IF(ISNUMBER(SEARCH("Approved",N20)),"승인",IF(N20="Closeout","종료",IF(N20="Maintenance","유지","진행"))) -> 유지 | Q20: =IF(P20="","",INDEX(시험별비교!$B$5:$B$25,MATCH(P20,시험별비교!$A$5:$A$25,0)))
A21: 13 | B21: 혈액암 | C21: Sonrotoclax | D21: BCL2i | E21: BGB-11417-204 | G21: Ph2 | H21: NCT06637501 | I21: TN CLL | J21: 94 | L21: Zanubrutinib | M21: CR/CRi | N21: Maintenance | O21: =IF(ISNUMBER(SEARCH("Approved",N21)),"승인",IF(N21="Closeout","종료",IF(N21="Maintenance","유지","진행"))) -> 유지 | Q21: =IF(P21="","",INDEX(시험별비교!$B$5:$B$25,MATCH(P21,시험별비교!$A$5:$A$25,0)))
A22: 13 | B22: 혈액암 | C22: Sonrotoclax | D22: BCL2i | E22: BGB-11417-301 | F22: CELESTIAL-TNCLL | G22: Ph3 | H22: NCT06073821 | I22: TN CLL/SLL (+Zanu) | J22: 711 | L22: Zanubrutinib | M22: PFS | N22: Maintenance | O22: =IF(ISNUMBER(SEARCH("Approved",N22)),"승인",IF(N22="Closeout","종료",IF(N22="Maintenance","유지","진행"))) -> 유지 | P22: 20 | Q22: =IF(P22="","",INDEX(시험별비교!$B$5:$B$25,MATCH(P22,시험별비교!$A$5:$A$25,0))) -> 모집완료
A23: 13 | B23: 혈액암 | C23: Sonrotoclax | D23: BCL2i | E23: BGB-11417-302 | F23: CELESTIAL-RRMCL | G23: Ph3 | H23: NCT06742996 | I23: R/R MCL | J23: 300 | L23: Zanubrutinib | M23: PFS | N23: Enrolling | O23: =IF(ISNUMBER(SEARCH("Approved",N23)),"승인",IF(N23="Closeout","종료",IF(N23="Maintenance","유지","진행"))) -> 진행 | P23: 15 | Q23: =IF(P23="","",INDEX(시험별비교!$B$5:$B$25,MATCH(P23,시험별비교!$A$5:$A$25,0))) -> 모집중
A24: 13 | B24: 혈액암 | C24: Sonrotoclax | D24: BCL2i | E24: BGB-11417-303 | F24: CELESTIAL-RRCLL | G24: Ph3 | H24: NCT06943872 | I24: R/R CLL/SLL | J24: 630 | L24: Obinutuzumab, Rituximab | M24: PFS | N24: Enrolling | O24: =IF(ISNUMBER(SEARCH("Approved",N24)),"승인",IF(N24="Closeout","종료",IF(N24="Maintenance","유지","진행"))) -> 진행 | P24: 11 | Q24: =IF(P24="","",INDEX(시험별비교!$B$5:$B$25,MATCH(P24,시험별비교!$A$5:$A$25,0))) -> 모집중
A25: 13 | B25: 혈액암 | C25: Sonrotoclax | D25: BCL2i | E25: BGB-11417-304 | F25: CELESTIAL-TNCLL2 | G25: Ph3 | H25: NCT07277231 | I25: TN CLL (vs acala + ven) | J25: 500 | L25: Zanubrutinib | M25: PFS | N25: Enrolling | O25: =IF(ISNUMBER(SEARCH("Approved",N25)),"승인",IF(N25="Closeout","종료",IF(N25="Maintenance","유지","진행"))) -> 진행 | P25: 5 | Q25: =IF(P25="","",INDEX(시험별비교!$B$5:$B$25,MATCH(P25,시험별비교!$A$5:$A$25,0))) -> 모집중
A26: 13 | B26: 혈액암 | C26: Sonrotoclax | D26: BCL2i | E26: BGB-11417-201 | G26: Ph2 | H26: NCT05471843 | I26: R/R MCL | J26: 124 | L26: - | M26: TEAEs, ORR | N26: Approved in CN and US; Maintenance ROW | O26: =IF(ISNUMBER(SEARCH("Approved",N26)),"승인",IF(N26="Closeout","종료",IF(N26="Maintenance","유지","진행"))) -> 승인 | Q26: =IF(P26="","",INDEX(시험별비교!$B$5:$B$25,MATCH(P26,시험별비교!$A$5:$A$25,0))) | R26: BEQALZI 미국·중국 승인 근거. EU 접수(R/R MCL)
A27: 13 | B27: 혈액암 | C27: Sonrotoclax | D27: BCL2i | E27: BGB-11417-202 | G27: Ph2 | H27: NCT05479994 | I27: R/R CLL | J27: 100 | L27: - | M27: ORR | N27: Approved | O27: =IF(ISNUMBER(SEARCH("Approved",N27)),"승인",IF(N27="Closeout","종료",IF(N27="Maintenance","유지","진행"))) -> 승인 | Q27: =IF(P27="","",INDEX(시험별비교!$B$5:$B$25,MATCH(P27,시험별비교!$A$5:$A$25,0))) | R27: 중국 R/R CLL 조건부 승인
A28: 14 | B28: 혈액암 | C28: Tacabrutideg | D28: BTK CDAC | E28: BGB-16673-101 | F28: CaDAnCe-101 | G28: Ph1/2 | H28: NCT05006716 | I28: B-Cell Malignancies | J28: 645 | L28: - | M28: TEAEs | N28: Enrolling | O28: =IF(ISNUMBER(SEARCH("Approved",N28)),"승인",IF(N28="Closeout","종료",IF(N28="Maintenance","유지","진행"))) -> 진행 | Q28: =IF(P28="","",INDEX(시험별비교!$B$5:$B$25,MATCH(P28,시험별비교!$A$5:$A$25,0)))
A29: 14 | B29: 혈액암 | C29: Tacabrutideg | D29: BTK CDAC | E29: BGB-16673-102 | G29: Ph1/2 | H29: NCT05294731 | I29: B-Cell Malignancies | J29: 146 | L29: - | M29: TEAEs, RP2D, ORR | N29: Enrolling | O29: =IF(ISNUMBER(SEARCH("Approved",N29)),"승인",IF(N29="Closeout","종료",IF(N29="Maintenance","유지","진행"))) -> 진행 | Q29: =IF(P29="","",INDEX(시험별비교!$B$5:$B$25,MATCH(P29,시험별비교!$A$5:$A$25,0)))
A30: 14 | B30: 혈액암 | C30: Tacabrutideg | D30: BTK CDAC | E30: BGB-16673-104 | F30: CaDAnCe-104 | G30: Ph1/2 | H30: NCT06634589 | I30: B-Cell Malignancies | J30: 80 | L30: Sonrotoclax, Zanubrutinib, Mosunetuzumab, Glofitamab | M30: DLTs, TEAEs | N30: Enrolling | O30: =IF(ISNUMBER(SEARCH("Approved",N30)),"승인",IF(N30="Closeout","종료",IF(N30="Maintenance","유지","진행"))) -> 진행 | Q30: =IF(P30="","",INDEX(시험별비교!$B$5:$B$25,MATCH(P30,시험별비교!$A$5:$A$25,0)))
A31: 14 | B31: 혈액암 | C31: Tacabrutideg | D31: BTK CDAC | E31: BGB-16673-302 | F31: CaDAnCe-302 | G31: Ph3 | H31: NCT06846671 | I31: R/R CLL/SLL (vs investigators choice) | J31: 250 | L31: - | M31: PFS | N31: Enrolling | O31: =IF(ISNUMBER(SEARCH("Approved",N31)),"승인",IF(N31="Closeout","종료",IF(N31="Maintenance","유지","진행"))) -> 진행 | P31: 9 | Q31: =IF(P31="","",INDEX(시험별비교!$B$5:$B$25,MATCH(P31,시험별비교!$A$5:$A$25,0))) -> 모집중
A32: 14 | B32: 혈액암 | C32: Tacabrutideg | D32: BTK CDAC | E32: BGB-16673-303 | F32: CaDAnCe-303 | G32: Ph3 | H32: NCT06970743 | I32: R/R CLL/SLL (CN) | J32: 152 | L32: - | M32: PFS | N32: Maintenance | O32: =IF(ISNUMBER(SEARCH("Approved",N32)),"승인",IF(N32="Closeout","종료",IF(N32="Maintenance","유지","진행"))) -> 유지 | Q32: =IF(P32="","",INDEX(시험별비교!$B$5:$B$25,MATCH(P32,시험별비교!$A$5:$A$25,0))) | R32: 중국 시험
A33: 14 | B33: 혈액암 | C33: Tacabrutideg | D33: BTK CDAC | E33: BGB-16673-304 | F33: CaDAnCe-304 | G33: Ph3 | H33: NCT06973187 | I33: R/R CLL/SLL (vs pirtobrutinib) | J33: 500 | L33: - | M33: PFS | N33: Enrolling | O33: =IF(ISNUMBER(SEARCH("Approved",N33)),"승인",IF(N33="Closeout","종료",IF(N33="Maintenance","유지","진행"))) -> 진행 | P33: 8 | Q33: =IF(P33="","",INDEX(시험별비교!$B$5:$B$25,MATCH(P33,시험별비교!$A$5:$A$25,0))) -> 모집중
A34: 15 | B34: 혈액암 | C34: BG-75202 | D34: KAT6A/Bi | E34: BGB-75202-102 | G34: Ph1 | H34: NCT07619287 | I34: Myeloid malignancies | J34: 118 | L34: Hypomethylation agent | M34: AEs, RDFE, CR/CRh | N34: Enrolling | O34: =IF(ISNUMBER(SEARCH("Approved",N34)),"승인",IF(N34="Closeout","종료",IF(N34="Maintenance","유지","진행"))) -> 진행 | Q34: =IF(P34="","",INDEX(시험별비교!$B$5:$B$25,MATCH(P34,시험별비교!$A$5:$A$25,0))) | R34: Q2 신규 Ph1 진입
A35: 15 | B35: 혈액암 | C35: Blinatumomab (BLINCYTO) | D35: CD19×CD3 BiTE | E35: BLINCYTO 20180257 | G35: Ph2 | H35: NCT04521231 | I35: R/R and MRD+ B-ALL | J35: 281 | K35: BeOne 지역 포함 전체 계획 등록 | L35: - | M35: CR/CRh, CR, MRD | N35: Maintenance | O35: =IF(ISNUMBER(SEARCH("Approved",N35)),"승인",IF(N35="Closeout","종료",IF(N35="Maintenance","유지","진행"))) -> 유지 | Q35: =IF(P35="","",INDEX(시험별비교!$B$5:$B$25,MATCH(P35,시험별비교!$A$5:$A$25,0))) | R35: Amgen 협력 (BeOne 판권 중국)
A36: 15 | B36: 혈액암 | C36: Blinatumomab (BLINCYTO) | D36: CD19×CD3 BiTE | E36: BLINCYTO 20190359 | G36: Ph2 | H36: NCT06054113 | I36: Pediatric R/R B-ALL | J36: 18 | L36: - | M36: CR/CRh | N36: Maintenance | O36: =IF(ISNUMBER(SEARCH("Approved",N36)),"승인",IF(N36="Closeout","종료",IF(N36="Maintenance","유지","진행"))) -> 유지 | Q36: =IF(P36="","",INDEX(시험별비교!$B$5:$B$25,MATCH(P36,시험별비교!$A$5:$A$25,0))) | R36: Amgen 협력 (BeOne 판권 중국)
A37: 16 | B37: 고형암 | C37: Tislelizumab | D37: PD-1 mAb | E37: BGB-A317-103 | G37: Ph1 | H37: NCT06091943 | I37: SubQ Formulation | J37: 59 | L37: - | M37: Bioavailability and Safety | N37: Closeout | O37: =IF(ISNUMBER(SEARCH("Approved",N37)),"승인",IF(N37="Closeout","종료",IF(N37="Maintenance","유지","진행"))) -> 종료 | Q37: =IF(P37="","",INDEX(시험별비교!$B$5:$B$25,MATCH(P37,시험별비교!$A$5:$A$25,0)))
A38: 16 | B38: 고형암 | C38: Tislelizumab | D38: PD-1 mAb | E38: BGB-HNSCC-201 | G38: Ph2 | H38: NCT05909904 | I38: 1L HNSCC | J38: 160 | L38: LAG3, TIM3 | M38: ORR | N38: Closeout | O38: =IF(ISNUMBER(SEARCH("Approved",N38)),"승인",IF(N38="Closeout","종료",IF(N38="Maintenance","유지","진행"))) -> 종료 | Q38: =IF(P38="","",INDEX(시험별비교!$B$5:$B$25,MATCH(P38,시험별비교!$A$5:$A$25,0)))
A39: 16 | B39: 고형암 | C39: Tislelizumab | D39: PD-1 mAb | E39: BGB-LC-201 | G39: Ph2 | H39: NCT05635708 | I39: 1L NSCLC | J39: 418 | L39: LAG3, OX40, HPK1, Chemotherapy | M39: ORR | N39: Closeout | O39: =IF(ISNUMBER(SEARCH("Approved",N39)),"승인",IF(N39="Closeout","종료",IF(N39="Maintenance","유지","진행"))) -> 종료 | Q39: =IF(P39="","",INDEX(시험별비교!$B$5:$B$25,MATCH(P39,시험별비교!$A$5:$A$25,0))) | R39: nedrug No.21(BGB-LC-203, PD-(L)1 경치료 NSCLC)과는 다른 시험
A40: 16 | B40: 고형암 | C40: Tislelizumab | D40: PD-1 mAb | E40: BGB-A317-217 | G40: Ph2 | H40: NCT07554521 | I40: 1L GC & ESCC | J40: 30 | L40: Chemotherapy | M40: AEs, SAEs | N40: Enrolling | O40: =IF(ISNUMBER(SEARCH("Approved",N40)),"승인",IF(N40="Closeout","종료",IF(N40="Maintenance","유지","진행"))) -> 진행 | Q40: =IF(P40="","",INDEX(시험별비교!$B$5:$B$25,MATCH(P40,시험별비교!$A$5:$A$25,0)))
A41: 16 | B41: 고형암 | C41: Tislelizumab | D41: PD-1 mAb | E41: BGB-A317-316 | G41: Ph3 | H41: NCT07043400 | I41: SubQ Formulation | J41: 351 | L41: Chemotherapy | M41: PK | N41: Enrolling | O41: =IF(ISNUMBER(SEARCH("Approved",N41)),"승인",IF(N41="Closeout","종료",IF(N41="Maintenance","유지","진행"))) -> 진행 | P41: 7 | Q41: =IF(P41="","",INDEX(시험별비교!$B$5:$B$25,MATCH(P41,시험별비교!$A$5:$A$25,0))) -> 모집중 | R41: 국내 적응증: 1L 위/위식도접합부 선암
...

Sheet 제품비교
A1: 상업화 제품 비교 — Appendix 'Commercial' 목록 ↔ nedrug 의약품등제품정보
A2: BeOne 상업화 제품 17종의 판권과 국내 허가 현황 (nedrug 2026-10-13 검색, 업체: 비원메디슨코리아(유))
A4: 제품 (Appendix) | B4: 성분 | C4: MOA | D4: BeOne 판권 | E4: 파트너 | F4: 국내 판권 보유 | G4: 국내 허가 여부 | H4: 국내 제품명 (nedrug) | I4: 허가일 | J4: 품목기준코드 | K4: 품목구분 | L4: 전문/희귀 | M4: 제조/수입 | N4: 수입제조국 | O4: ATC코드 | P4: 신약구분 | Q4: 비고
A5: BRUKINSA® | B5: zanubrutinib | C5: BTKi | D5: Global | E5: - | F5: =IF(D5="China","N","Y") -> Y | G5: =IF(F5="N","해당 없음",IF(H5="","미허가","허가")) -> 허가 | H5: 브루킨사캡슐80밀리그램(자누브루티닙) | I5: 44616 | J5: 202200854 | K5: 의약품 | L5: 전문의약품 | M5: 수입 | N5: 미국 | O5: L01EL03 | P5: Y | Q5: 정제(BGB-3111-114: 주요국 승인, 일본 접수)는 국내 미허가 → 제형 추가(LCM) 과제
A6: TEVIMBRA® | B6: tislelizumab | C6: PD-1 mAb | D6: Global | E6: - | F6: =IF(D6="China","N","Y") -> Y | G6: =IF(F6="N","해당 없음",IF(H6="","미허가","허가")) -> 허가 | H6: 테빔브라주(티슬렐리주맙) | I6: 45250 | J6: 202303165 | K6: 생물의약품 | L6: 전문의약품 | M6: 수입 | N6: 중국,아일랜드 | O6: L01FF09 | P6: Y | Q6: SC 제형 3상(BGB-A317-316)에 한국 참여 중 → 향후 SC 제형 허가 가능
A7: BEQALZI™ | B7: sonrotoclax | C7: BCL2i | D7: Global | E7: - | F7: =IF(D7="China","N","Y") -> Y | G7: =IF(F7="N","해당 없음",IF(H7="","미허가","허가")) -> 미허가 | Q7: 미국(R/R MCL)·중국(R/R MCL·CLL) 승인, EU(R/R MCL) 접수. 국내 3상 4건 진행 중 → 다음 국내 허가 후보
A8: ZIIHERA® | B8: zanidatamab | C8: HER2 bsAb | D8: APAC (일본·인도 제외) | E8: Zymeworks / Jazz | F8: =IF(D8="China","N","Y") -> Y | G8: =IF(F8="N","해당 없음",IF(H8="","미허가","허가")) -> 허가 | H8: 지헤라주300mg(자니다타맙) | I8: 46100 | J8: 202600793 | K8: 생물의약품 | L8: 전문의약품(희귀) | M8: 수입 | N8: 중국 | O8: L01FD07 | P8: N | Q8: 근거 시험은 HERIZON-BTC-01(2L+ BTC)로 추정. 1L HER2+ GEA(ZW25-301)는 미국·중국 접수 → 국내 적응증 확대 후보
A9: IMDELLTRA® | B9: tarlatamab | C9: DLL3×CD3 BiTE | D9: China | E9: Amgen | F9: =IF(D9="China","N","Y") -> N | G9: =IF(F9="N","해당 없음",IF(H9="","미허가","허가")) -> 해당 없음 | Q9: BeOne 판권은 중국 한정 → 국내 해당 없음
A10: XGEVA® | B10: denosumab | C10: RANKL mAb | D10: China | E10: Amgen | F10: =IF(D10="China","N","Y") -> N | G10: =IF(F10="N","해당 없음",IF(H10="","미허가","허가")) -> 해당 없음 | Q10: BeOne 판권은 중국 한정 → 국내 해당 없음
A11: BLINCYTO® | B11: blinatumomab | C11: CD19×CD3 BiTE | D11: China | E11: Amgen | F11: =IF(D11="China","N","Y") -> N | G11: =IF(F11="N","해당 없음",IF(H11="","미허가","허가")) -> 해당 없음 | Q11: BeOne 판권은 중국 한정 → 국내 해당 없음
A12: KYPROLIS® | B12: carfilzomib | C12: Proteasome inhibitor | D12: China | E12: Amgen | F12: =IF(D12="China","N","Y") -> N | G12: =IF(F12="N","해당 없음",IF(H12="","미허가","허가")) -> 해당 없음 | Q12: BeOne 판권은 중국 한정 → 국내 해당 없음
A13: SYLVANT® | B13: siltuximab | C13: IL-6 mAb | D13: China | E13: Recordati | F13: =IF(D13="China","N","Y") -> N | G13: =IF(F13="N","해당 없음",IF(H13="","미허가","허가")) -> 해당 없음 | Q13: BeOne 판권은 중국 한정 → 국내 해당 없음
A14: QARZIBA® | B14: dinutuximab beta | C14: GD2 mAb | D14: China | E14: Recordati | F14: =IF(D14="China","N","Y") -> N | G14: =IF(F14="N","해당 없음",IF(H14="","미허가","허가")) -> 해당 없음 | Q14: BeOne 판권은 중국 한정 → 국내 해당 없음
A15: TAFINLAR® | B15: dabrafenib | C15: BRAFi | D15: China | E15: Novartis | F15: =IF(D15="China","N","Y") -> N | G15: =IF(F15="N","해당 없음",IF(H15="","미허가","허가")) -> 해당 없음 | Q15: BeOne 판권은 중국 한정 → 국내 해당 없음
A16: MEKINIST® | B16: trametinib | C16: MEKi | D16: China | E16: Novartis | F16: =IF(D16="China","N","Y") -> N | G16: =IF(F16="N","해당 없음",IF(H16="","미허가","허가")) -> 해당 없음 | Q16: BeOne 판권은 중국 한정 → 국내 해당 없음
A17: VOTRIENT® | B17: pazopanib | C17: VEGFR TKI | D17: China | E17: Novartis | F17: =IF(D17="China","N","Y") -> N | G17: =IF(F17="N","해당 없음",IF(H17="","미허가","허가")) -> 해당 없음 | Q17: BeOne 판권은 중국 한정 → 국내 해당 없음
A18: AFINITOR® | B18: everolimus | C18: mTORi | D18: China | E18: Novartis | F18: =IF(D18="China","N","Y") -> N | G18: =IF(F18="N","해당 없음",IF(H18="","미허가","허가")) -> 해당 없음 | Q18: BeOne 판권은 중국 한정 → 국내 해당 없음
A19: ZYKADIA® | B19: ceritinib | C19: ALKi | D19: China | E19: Novartis | F19: =IF(D19="China","N","Y") -> N | G19: =IF(F19="N","해당 없음",IF(H19="","미허가","허가")) -> 해당 없음 | Q19: BeOne 판권은 중국 한정 → 국내 해당 없음
A20: POBEVCY® | B20: bevacizumab biosimilar | C20: VEGF mAb | D20: China | E20: Bio-Thera | F20: =IF(D20="China","N","Y") -> N | G20: =IF(F20="N","해당 없음",IF(H20="","미허가","허가")) -> 해당 없음 | Q20: BeOne 판권은 중국 한정 → 국내 해당 없음
A21: BAITUOWEI® | B21: goserelin microspheres | C21: GnRH agonist | D21: China | E21: Luye Pharma | F21: =IF(D21="China","N","Y") -> N | G21: =IF(F21="N","해당 없음",IF(H21="","미허가","허가")) -> 해당 없음 | Q21: BeOne 판권은 중국 한정 → 국내 해당 없음
A23: 국내 판권 보유(수식): BeOne 판권이 'China'가 아니면 Y. 국내 허가 여부(수식): 판권 없음 → 해당 없음 / nedrug 제품명이 있으면 허가 / 없으면 미허가.
A24: MOA는 작성자가 보충한 값임 (Appendix 'Commercial' 목록에는 MOA가 없음). BEQALZI 승인 현황은 Appendix p.23 각주 3과 8월 파이프라인 'Accepted submissions'에서 가져옴.
A25: Source: Q2_2026_earnings_-_Clinical_Trials_Appendix_-_FINAL.pdf p.23 · BeOne_nedrug_20261013_의약품등제품정보목록.xlsx · BeOne-website-pipeline-Aug-2026.pdf
